Workbook

Sheet Artist Profile Data (Weekly)
A1: TPI Flag | B1: Week # | C1: Date | D1: <<>> | E1: Artist Name | F1: Country | G1: Genre | H1: Label | I1: Viberate Rank | J1: Spotify Rank | K1: Spotify Followers Total | L1: Spotify Streams Total | M1: Spotify Monthly Listeners Total | N1: Spotify Playlist Reach Total | O1: YouTube Rank | P1: YouTube Subscribers Total | Q1: YouTube Views Total | R1: YouTube Likes Total | S1: Social Rank | T1: TikTok Followers Total | U1: Instagram Followers Total | V1: Facebook Followers Total | W1: Deezer Fans Total | X1: SoundCloud Followers Total | Y1: Radio Airplay Rank | Z1: Beatport Rank | AA1: Beatport Tracks Total | AB1: Beatport Tracks in Top 100 Total | AC1: Beatport Days in Top 100 Total | AD1: Beatport Track Performance Points Total
A2: =_xlfn.XLOOKUP(E2,Lookups!$E:$E,Lookups!$F:$F,0) -> 0 | B2: 1 | C2: 2026-07-03 | E2: William Last KRM | F2: South Africa | G2: Hip Hop | H2: N/A | I2: 553 | J2: 113603 | K2: 48057 | L2: 6267875 | M2: 38782 | N2: 172378 | O2: 884 | P2: 3330000 | Q2: 1623986472 | R2: 53101116 | S2: 46 | T2: 31309236 | U2: 11966741 | V2: 12384786 | W2: 2505 | X2: 396 | Y2: 63835 | Z2: 66845 | AA2: 21 | AB2: 0 | AC2: 0 | AD2: 14.602268
A3: =_xlfn.XLOOKUP(E3,Lookups!$E:$E,Lookups!$F:$F,0) -> 1 | B3: 1 | C3: 2026-07-03 | E3: DJ Maphorisa | F3: South Africa | G3: Electronic | H3: Big Indie Labels, Sony Music Entertainment, Universal Music Group, Warner Music Group | I3: 1168 | J3: 2019 | K3: 4458982 | L3: 1463831442 | M3: 4691122 | N3: 15589707 | O3: 1478 | P3: 1430000 | Q3: 968947488 | R3: 6167873 | S3: 1870 | T3: 2398604 | U3: 3757172 | V3: 4656475 | W3: 226389 | X3: 41685 | Y3: 13936 | Z3: 4253 | AA3: 634 | AB3: 10 | AC3: 69 | AD3: 1250.5563
A4: =_xlfn.XLOOKUP(E4,Lookups!$E:$E,Lookups!$F:$F,0) -> 1 | B4: 1 | C4: 2026-07-03 | E4: Kabza De Small | F4: South Africa | G4: Electronic | H4: Big Indie Labels, Universal Music Group, Sony Music Entertainment, Warner Music Group | I4: 1332 | J4: 1703 | K4: 7907778 | L4: 1149482954 | M4: 3813927 | N4: 11131799 | O4: 3618 | P4: 594000 | Q4: 514501598 | R4: 3140157 | S4: 3620 | T4: 466487 | U4: 3152350 | V4: 2130400 | W4: 225391 | X4: 23881 | Y4: 5727 | Z4: 4352 | AA4: 791 | AB4: 10 | AC4: 101 | AD4: 1452.8398
A5: =_xlfn.XLOOKUP(E5,Lookups!$E:$E,Lookups!$F:$F,0) -> 0 | B5: 1 | C5: 2026-07-03 | E5: Triplets Ghetto Kids | F5: Uganda | G5: African | H5: Universal Music Group | I5: 1618 | J5: 448334 | K5: 983 | L5: 381424 | M5: 1174 | N5: 3198 | O5: 2194 | P5: 2180000 | Q5: 860697969 | R5: 10643567 | S5: 557 | T5: 13117502 | U5: 9486592 | V5: 7717773 | W5: 167 | X5: 294 | Y5: 466238 | Z5: N/A | AA5: N/A | AB5: N/A | AC5: N/A | AD5: N/A
A6: =_xlfn.XLOOKUP(E6,Lookups!$E:$E,Lookups!$F:$F,0) -> 0 | B6: 1 | C6: 2026-07-03 | E6: MaWhoo | F6: South Africa | G6: African | H6: Big Indie Labels, Universal Music Group, Sony Music Entertainment, Warner Music Group | I6: 1929 | J6: 4233 | K6: 2270672 | L6: 369060161 | M6: 2044279 | N6: 7895082 | O6: 2849 | P6: 474000 | Q6: 201857520 | R6: 1200071 | S6: 1233 | T6: 2334151 | U6: 1220117 | V6: 2850347 | W6: 7847 | X6: N/A | Y6: 24055 | Z6: 9391 | AA6: 207 | AB6: 0 | AC6: 0 | AD6: 282.23208
A7: =_xlfn.XLOOKUP(E7,Lookups!$E:$E,Lookups!$F:$F,0) -> 1 | B7: 1 | C7: 2026-07-03 | E7: Zee Nxumalo | F7: South Africa | G7: African | H7: Big Indie Labels, Universal Music Group, Warner Music Group, Sony Music Entertainment | I7: 2142 | J7: 4568 | K7: 1693660 | L7: 271735115 | M7: 2017591 | N7: 7436139 | O7: 4189 | P7: 365000 | Q7: 128930678 | R7: 1445530 | S7: 867 | T7: 3388867 | U7: 1312192 | V7: 2299288 | W7: 3641 | X7: 312 | Y7: 30061 | Z7: 10719 | AA7: 112 | AB7: 3 | AC7: 22 | AD7: 169.00342
A8: =_xlfn.XLOOKUP(E8,Lookups!$E:$E,Lookups!$F:$F,0) -> 1 | B8: 1 | C8: 2026-07-03 | E8: Kelvin Momo | F8: South Africa | G8: Electronic | H8: Big Indie Labels, Universal Music Group, Sony Music Entertainment, Warner Music Group | I8: 2544 | J8: 2895 | K8: 4669030 | L8: 620779039 | M8: 1667314 | N8: 4143914 | O8: 4409 | P8: 542000 | Q8: 231085759 | R8: 1577531 | S8: 8638 | T8: 145620 | U8: 1159358 | V8: 320638 | W8: 34772 | X8: 5131 | Y8: 18580 | Z8: 5436 | AA8: 429 | AB8: 0 | AC8: 0 | AD8: 617.31407
A9: =_xlfn.XLOOKUP(E9,Lookups!$E:$E,Lookups!$F:$F,0) -> 1 | B9: 1 | C9: 2026-07-03 | E9: Uncle Waffles | F9: South Africa | G9: Electronic | H9: Big Indie Labels, Sony Music Entertainment | I9: 2570 | J9: 6650 | K9: 1601098 | L9: 208116967 | M9: 1544604 | N9: 7449538 | O9: 4653 | P9: 582000 | Q9: 157049282 | R9: 1743842 | S9: 1050 | T9: 3815185 | U9: 3524682 | V9: 36156 | W9: 12279 | X9: 11000 | Y9: 26090 | Z9: 1573 | AA9: 38 | AB9: 2 | AC9: 206 | AD9: 3361.5129
A10: =_xlfn.XLOOKUP(E10,Lookups!$E:$E,Lookups!$F:$F,0) -> 0 | B10: 1 | C10: 2026-07-03 | E10: Makhadzi | F10: South Africa | G10: Electronic | H10: Big Indie Labels, Warner Music Group, Universal Music Group | I10: 2633 | J10: 12423 | K10: 1627606 | L10: 243726648 | M10: 396334 | N10: 1334147 | O10: 2059 | P10: 1020000 | Q10: 763322676 | R10: 3270138 | S10: 871 | T10: 4140718 | U10: 1438627 | V10: 8623765 | W10: 77596 | X10: N/A | Y10: 23865 | Z10: 22176 | AA10: 160 | AB10: 0 | AC10: 0 | AD10: 191.83221
A11: =_xlfn.XLOOKUP(E11,Lookups!$E:$E,Lookups!$F:$F,0) -> 0 | B11: 1 | C11: 2026-07-03 | E11: Zinoleesky | F11: Nigeria | G11: African | H11: Big Indie Labels, Universal Music Group | I11: 2909 | J11: 3323 | K11: 3019863 | L11: 699218918 | M11: 2460115 | N11: 6807145 | O11: 11804 | P11: 293000 | Q11: 114547876 | R11: 1035273 | S11: 5298 | T11: 542139 | U11: 2509418 | V11: 500878 | W11: 62407 | X11: N/A | Y11: 5759 | Z11: N/A | AA11: N/A | AB11: N/A | AC11: N/A | AD11: N/A
A12: =_xlfn.XLOOKUP(E12,Lookups!$E:$E,Lookups!$F:$F,0) -> 1 | B12: 1 | C12: 2026-07-03 | E12: Focalistic | F12: South Africa | G12: Electronic | H12: Big Indie Labels, Universal Music Group, Warner Music Group, Sony Music Entertainment | I12: 3339 | J12: 6372 | K12: 1570892 | L12: 386533451 | M12: 2458020 | N12: 9602399 | O12: 8333 | P12: 495000 | Q12: 251206642 | R12: 2038557 | S12: 2419 | T12: 1589188 | U12: 2679918 | V12: 3716982 | W12: 74201 | X12: 8661 | Y12: 13233 | Z12: 9113 | AA12: 266 | AB12: 4 | AC12: 30 | AD12: 382.84255
A13: =_xlfn.XLOOKUP(E13,Lookups!$E:$E,Lookups!$F:$F,0) -> 1 | B13: 1 | C13: 2026-07-03 | E13: Sam Deep | F13: South Africa | G13: African | H13: Universal Music Group, Big Indie Labels, Sony Music Entertainment | I13: 3404 | J13: 5795 | K13: 1275926 | L13: 186616030 | M13: 1685783 | N13: 3957091 | O13: 4260 | P13: 324000 | Q13: 187645002 | R13: 1017407 | S13: 7100 | T13: 233735 | U13: 309818 | V13: N/A | W13: 5700 | X13: 21 | Y13: 34914 | Z13: N/A | AA13: N/A | AB13: N/A | AC13: N/A | AD13: N/A
A14: =_xlfn.XLOOKUP(E14,Lookups!$E:$E,Lookups!$F:$F,0) -> 0 | B14: 1 | C14: 2026-07-03 | E14: Ghost Hlubi | F14: South Africa | G14: Hip Hop | H14: Other Indie / Unsigned | I14: 3510 | J14: 292385 | K14: 8235 | L14: 278400 | M14: 1935 | N14: 8 | O14: 1703 | P14: 1540000 | Q14: 246739795 | R14: 9406433 | S14: 1006 | T14: 2451369 | U14: 1560932 | V14: 44060 | W14: 16 | X14: N/A | Y14: 466238 | Z14: N/A | AA14: N/A | AB14: N/A | AC14: N/A | AD14: N/A
A15: =_xlfn.XLOOKUP(E15,Lookups!$E:$E,Lookups!$F:$F,0) -> 1 | B15: 1 | C15: 2026-07-03 | E15: Scotts Maphuma | F15: South Africa | G15: Electronic | H15: Big Indie Labels, Sony Music Entertainment, Universal Music Group, Warner Music Group | I15: 3583 | J15: 3931 | K15: 1838533 | L15: 461935885 | M15: 2823644 | N15: 11186792 | O15: 613359 | P15: N/A | Q15: N/A | R15: N/A | S15: 6356 | T15: N/A | U15: 1321490 | V15: N/A | W15: 5281 | X15: 627 | Y15: 79539 | Z15: N/A | AA15: N/A | AB15: N/A | AC15: N/A | AD15: N/A
A16: =_xlfn.XLOOKUP(E16,Lookups!$E:$E,Lookups!$F:$F,0) -> 0 | B16: 1 | C16: 2026-07-03 | E16: Cassper Nyovest | F16: South Africa | G16: Electronic | H16: Universal Music Group, Big Indie Labels, Sony Music Entertainment | I16: 3611 | J16: 10359 | K16: 1496389 | L16: 208911298 | M16: 840239 | N16: 2723270 | O16: 8173 | P16: 563000 | Q16: 295837867 | R16: 2933637 | S16: 1774 | T16: 2830334 | U16: 6516655 | V16: 7110438 | W16: 261030 | X16: 27928 | Y16: 9283 | Z16: 17134 | AA16: 214 | AB16: 0 | AC16: 0 | AD16: 397.72838
A17: =_xlfn.XLOOKUP(E17,Lookups!$E:$E,Lookups!$F:$F,0) -> 1 | B17: 1 | C17: 2026-07-03 | E17: Mr JazziQ | F17: South Africa | G17: Electronic | H17: Big Indie Labels, Warner Music Group | I17: 3639 | J17: 8313 | K17: 2146180 | L17: 223599478 | M17: 802700 | N17: 2970443 | O17: 8518 | P17: 543000 | Q17: 228312985 | R17: 1846865 | S17: 1100 | T17: 3119631 | U17: 2276521 | V17: 3241005 | W17: 67112 | X17: 4061 | Y17: 18447 | Z17: 21089 | AA17: 131 | AB17: 0 | AC17: 0 | AD17: 194.33923
A18: =_xlfn.XLOOKUP(E18,Lookups!$E:$E,Lookups!$F:$F,0) -> 0 | B18: 1 | C18: 2026-07-03 | E18: Master KG | F18: South Africa | G18: Electronic | H18: Warner Music Group, Big Indie Labels, Sony Music Entertainment | I18: 3797 | J18: 3846 | K18: 708600 | L18: 1095288410 | M18: 4495301 | N18: 16870953 | O18: 4076 | P18: 138 | Q18: 1245441970 | R18: 8795574 | S18: 7504 | T18: 1814526 | U18: 1975824 | V18: 4050014 | W18: 93376 | X18: N/A | Y18: 1779 | Z18: 19628 | AA18: 166 | AB18: 2 | AC18: 38 | AD18: 301.78627
A19: =_xlfn.XLOOKUP(E19,Lookups!$E:$E,Lookups!$F:$F,0) -> 0 | B19: 1 | C19: 2026-07-03 | E19: Shimza | F19: South Africa | G19: Electronic | H19: Big Indie Labels, Universal Music Group, Sony Music Entertainment | I19: 3901 | J19: 4327 | K19: 257255 | L19: 321431996 | M19: 6157309 | N19: 47834694 | O19: 22790 | P19: 77600 | Q19: 31980373 | R19: 313948 | S19: 2728 | T19: 373115 | U19: 1277880 | V19: 1840460 | W19: 21674 | X19: 43157 | Y19: 7295 | Z19: 123905 | AA19: 28 | AB19: 1 | AC19: 2 | AD19: 14.804325
A20: =_xlfn.XLOOKUP(E20,Lookups!$E:$E,Lookups!$F:$F,0) -> 0 | B20: 1 | C20: 2026-07-03 | E20: Babalwa M | F20: South Africa | G20: Electronic | H20: Universal Music Group, Big Indie Labels | I20: 4171 | J20: 5747 | K20: 1558102 | L20: 326612473 | M20: 1604568 | N20: 4476345 | O20: 10438 | P20: 178000 | Q20: 47241821 | R20: 300543 | S20: 9730 | T20: 707010 | U20: 567916 | V20: 61511 | W20: 13041 | X20: N/A | Y20: 27006 | Z20: 12555 | AA20: 121 | AB20: 1 | AC20: 23 | AD20: 161.03616
A21: =_xlfn.XLOOKUP(E21,Lookups!$E:$E,Lookups!$F:$F,0) -> 0 | B21: 1 | C21: 2026-07-03 | E21: Nkosazana Daughter | F21: South Africa | G21: Electronic | H21: Big Indie Labels, Universal Music Group, Sony Music Entertainment, Warner Music Group | I21: 4585 | J21: 8450 | K21: 937268 | L21: 402161640 | M21: 1288579 | N21: 3416575 | O21: 56949 | P21: 1830 | Q21: 22907413 | R21: 169750 | S21: 3155 | T21: 3911453 | U21: 2775933 | V21: 127 | W21: 11296 | X21: N/A | Y21: 25019 | Z21: 11949 | AA21: 170 | AB21: 0 | AC21: 0 | AD21: 242.09327
A22: =_xlfn.XLOOKUP(E22,Lookups!$E:$E,Lookups!$F:$F,0) -> 0 | B22: 1 | C22: 2026-07-03 | E22: Dlala Thukzin | F22: South Africa | G22: Electronic | H22: Universal Music Group, Big Indie Labels | I22: 4704 | J22: 5440 | K22: 1906580 | L22: 295608849 | M22: 1477500 | N22: 5066848 | O22: 148002 | P22: 2350 | Q22: 962765 | R22: 9150 | S22: 7460 | T22: 561417 | U22: 555164 | V22: 1198433 | W22: 11606 | X22: 2128 | Y22: 18446 | Z22: 6130 | AA22: 130 | AB22: 6 | AC22: 38 | AD22: 479.08908
A23: =_xlfn.XLOOKUP(E23,Lookups!$E:$E,Lookups!$F:$F,0) -> 1 | B23: 1 | C23: 2026-07-03 | E23: Tyler ICU | F23: South Africa | G23: Electronic | H23: Big Indie Labels, Sony Music Entertainment, Universal Music Group, Warner Music Group | I23: 4773 | J23: 6304 | K23: 1551136 | L23: 420009551 | M23: 2278538 | N23: 5958557 | O23: 4597 | P23: 579000 | Q23: 363221124 | R23: 2396399 | S23: 9200 | T23: 591043 | U23: 817068 | V23: 1618568 | W23: 46576 | X23: 1287 | Y23: 13761 | Z23: 2673 | AA23: 266 | AB23: 2 | AC23: 79 | AD23: 1402.7406
A24: =_xlfn.XLOOKUP(E24,Lookups!$E:$E,Lookups!$F:$F,0) -> 0 | B24: 1 | C24: 2026-07-03 | E24: Young Stunna | F24: South Africa | G24: Electronic | H24: Big Indie Labels, Sony Music Entertainment, Universal Music Group, Warner Music Group | I24: 4984 | J24: 7090 | K24: 1938748 | L24: 426874353 | M24: 1053355 | N24: 3784951 | O24: 14094 | P24: 194000 | Q24: 100507942 | R24: 622554 | S24: 7700 | T24: 37112 | U24: 1577419 | V24: 1461443 | W24: 35143 | X24: 1129 | Y24: 55837 | Z24: 15935 | AA24: 150 | AB24: 1 | AC24: 3 | AD24: 199.55947
A25: =_xlfn.XLOOKUP(E25,Lookups!$E:$E,Lookups!$F:$F,0) -> 0 | B25: 1 | C25: 2026-07-03 | E25: Major League DJz | F25: South Africa | G25: Electronic | H25: Big Indie Labels, Warner Music Group, Universal Music Group, Sony Music Entertainment, BMG | I25: 5041 | J25: 9838 | K25: 909018 | L25: 188140413 | M25: 1560493 | N25: 12730595 | O25: 4632 | P25: 1190000 | Q25: 386123717 | R25: 3685385 | S25: 5512 | T25: 865437 | U25: 2122444 | V25: 3408361 | W25: 53604 | X25: 18673 | Y25: 7480 | Z25: 2372 | AA25: 294 | AB25: 13 | AC25: 221 | AD25: 1710.1772
A26: =_xlfn.XLOOKUP(E26,Lookups!$E:$E,Lookups!$F:$F,0) -> 0 | B26: 1 | C26: 2026-07-03 | E26: Boohle | F26: South Africa | G26: Electronic | H26: Universal Music Group, Big Indie Labels, Warner Music Group, Sony Music Entertainment | I26: 5508 | J26: 9358 | K26: 1246204 | L26: 189625876 | M26: 1539270 | N26: 5185813 | O26: 16299 | P26: 125000 | Q26: 122051824 | R26: 919253 | S26: 3649 | T26: 827405 | U26: 1480176 | V26: 226356 | W26: 33937 | X26: N/A | Y26: 10938 | Z26: 19093 | AA26: 133 | AB26: 2 | AC26: 21 | AD26: 157.80448
A27: =_xlfn.XLOOKUP(E27,Lookups!$E:$E,Lookups!$F:$F,0) -> 0 | B27: 1 | C27: 2026-07-03 | E27: Al Xapo | F27: South Africa | G27: Electronic | H27: Big Indie Labels, Sony Music Entertainment, Warner Music Group, Universal Music Group | I27: 5779 | J27: 7168 | K27: 134574 | L27: 165911119 | M27: 2404098 | N27: 11205662 | O27: 8731 | P27: 135000 | Q27: 50720662 | R27: 309574 | S27: 148287 | T27: 5691 | U27: 53006 | V27: N/A | W27: 237 | X27: 117 | Y27: 90105 | Z27: N/A | AA27: N/A | AB27: N/A | AC27: N/A | AD27: N/A
A28: =_xlfn.XLOOKUP(E28,Lookups!$E:$E,Lookups!$F:$F,0) -> 0 | B28: 1 | C28: 2026-07-03 | E28: Aymos | F28: South Africa | G28: Electronic | H28: Universal Music Group, Big Indie Labels, Sony Music Entertainment | I28: 6034 | J28: 8714 | K28: 1716554 | L28: 221645763 | M28: 920077 | N28: 2337015 | O28: 8882 | P28: 381000 | Q28: 194839906 | R28: 1142159 | S28: 6114 | T28: 1131062 | U28: 791511 | V28: 22484 | W28: 28714 | X28: N/A | Y28: 33375 | Z28: 16489 | AA28: 133 | AB28: 1 | AC28: 23 | AD28: 192.20437
A29: =_xlfn.XLOOKUP(E29,Lookups!$E:$E,Lookups!$F:$F,0) -> 0 | B29: 1 | C29: 2026-07-03 | E29: DJ Zinhle | F29: South Africa | G29: Electronic | H29: Big Indie Labels, Universal Music Group | I29: 6082 | J29: 22395 | K29: 271970 | L29: 41360254 | M29: 1066822 | N29: 1629728 | O29: 25735 | P29: 164000 | Q29: 46530532 | R29: 333785 | S29: 1614 | T29: 2081911 | U29: 5641967 | V29: 4107115 | W29: 70209 | X29: N/A | Y29: 30972 | Z29: 67544 | AA29: 37 | AB29: 0 | AC29: 0 | AD29: 31.631415
A30: =_xlfn.XLOOKUP(E30,Lookups!$E:$E,Lookups!$F:$F,0) -> 1 | B30: 1 | C30: 2026-07-03 | E30: TXC | F30: South Africa | G30: Electronic | H30: Big Indie Labels | I30: 6520 | J30: 11455 | K30: 318313 | L30: 98169042 | M30: 1995769 | N30: 8865208 | O30: 3676 | P30: 443000 | Q30: 86418178 | R30: 1024426 | S30: 6498 | T30: 2066155 | U30: 196750 | V30: 441978 | W30: 1689 | X30: 491 | Y30: 102629 | Z30: N/A | AA30: N/A | AB30: N/A | AC30: N/A | AD30: N/A
A31: =_xlfn.XLOOKUP(E31,Lookups!$E:$E,Lookups!$F:$F,0) -> 1 | B31: 1 | C31: 2026-07-03 | E31: Mellow & Sleazy | F31: South Africa | G31: Electronic | H31: Big Indie Labels, Sony Music Entertainment, Universal Music Group, Warner Music Group | I31: 6605 | J31: 6447 | K31: 2097947 | L31: 465967624 | M31: 1469069 | N31: 4744746 | O31: 14770 | P31: 283000 | Q31: 134581637 | R31: 1100673 | S31: 23054 | T31: 348801 | U31: 727954 | V31: 93442 | W31: 32545 | X31: 711 | Y31: 30492 | Z31: 5280 | AA31: 411 | AB31: 0 | AC31: 0 | AD31: 649.03419
A32: =_xlfn.XLOOKUP(E32,Lookups!$E:$E,Lookups!$F:$F,0) -> 0 | B32: 1 | C32: 2026-07-03 | E32: Busta 929 | F32: South Africa | G32: Electronic | H32: Big Indie Labels | I32: 6786 | J32: 12742 | K32: 1289612 | L32: 138837695 | M32: 730585 | N32: 1472656 | O32: 7622 | P32: 374000 | Q32: 209535054 | R32: 1406589 | S32: 10584 | T32: N/A | U32: 1361475 | V32: 1626694 | W32: 54680 | X32: N/A | Y32: 18923 | Z32: 6089 | AA32: 334 | AB32: 5 | AC32: 33 | AD32: 517.54834
A33: =_xlfn.XLOOKUP(E33,Lookups!$E:$E,Lookups!$F:$F,0) -> 1 | B33: 1 | C33: 2026-07-03 | E33: Xduppy | F33: South Africa | G33: Electronic | H33: Big Indie Labels, Sony Music Entertainment, Universal Music Group, Warner Music Group | I33: 6796 | J33: 6705 | K33: 492332 | L33: 286861518 | M33: 2277376 | N33: 6810311 | O33: 235532 | P33: 136 | Q33: 2375 | R33: 60 | S33: 4595 | T33: 530317 | U33: 320385 | V33: N/A | W33: 2750 | X33: 34 | Y33: 65871 | Z33: 5978 | AA33: 239 | AB33: 0 | AC33: 0 | AD33: 439.08656
A34: =_xlfn.XLOOKUP(E34,Lookups!$E:$E,Lookups!$F:$F,0) -> 0 | B34: 1 | C34: 2026-07-03 | E34: DJ Tira | F34: South Africa | G34: Electronic | H34: Big Indie Labels, Universal Music Group | I34: 6835 | J34: 16316 | K34: 681589 | L34: 119046469 | M34: 563892 | N34: 2524859 | O34: 21282 | P34: N/A | Q34: 203940883 | R34: 1240126 | S34: 1444 | T34: 1317267 | U34: 3369547 | V34: 5278925 | W34: 48447 | X34: 423 | Y34: 14252 | Z34: 6569 | AA34: 277 | AB34: 16 | AC34: 224 | AD34: 833.01558
A35: =_xlfn.XLOOKUP(E35,Lookups!$E:$E,Lookups!$F:$F,0) -> 0 | B35: 1 | C35: 2026-07-03 | E35: Dj Karri | F35: South Africa | G35: Electronic | H35: Big Indie Labels | I35: 7234 | J35: 32553 | K35: 209300 | L35: 29876414 | M35: 435727 | N35: 749079 | O35: 19922 | P35: 103000 | Q35: 21119138 | R35: 213264 | S35: 388 | T35: 2850937 | U35: 673726 | V35: 2083381 | W35: 712 | X35: N/A | Y35: 91088 | Z35: N/A | AA35: N/A | AB35: N/A | AC35: N/A | AD35: N/A
A36: =_xlfn.XLOOKUP(E36,Lookups!$E:$E,Lookups!$F:$F,0) -> 0 | B36: 1 | C36: 2026-07-03 | E36: Kidd Carder | F36: Nigeria | G36: African | H36: Big Indie Labels | I36: 7385 | J36: 10101 | K36: 230873 | L36: 107450555 | M36: 2148782 | N36: 9277828 | O36: 23654 | P36: 19000 | Q36: 9650814 | R36: 59258 | S36: 5105 | T36: 171453 | U36: 105752 | V36: 35 | W36: 172 | X36: N/A | Y36: 63537 | Z36: N/A | AA36: N/A | AB36: N/A | AC36: N/A | AD36: N/A
A37: =_xlfn.XLOOKUP(E37,Lookups!$E:$E,Lookups!$F:$F,0) -> 0 | B37: 1 | C37: 2026-07-03 | E37: Sun-EL Musician | F37: South Africa | G37: Electronic | H37: Big Indie Labels, Universal Music Group, Sony Music Entertainment | I37: 7457 | J37: 12757 | K37: 947451 | L37: 218288307 | M37: 937514 | N37: 2744061 | O37: 13564 | P37: 235000 | Q37: 185962695 | R37: 1291159 | S37: 13411 | T37: 141667 | U37: 307864 | V37: 1109825 | W37: 119239 | X37: 10697 | Y37: 7780 | Z37: 7153 | AA37: 153 | AB37: 5 | AC37: 68 | AD37: 545.06582
A38: =_xlfn.XLOOKUP(E38,Lookups!$E:$E,Lookups!$F:$F,0) -> 0 | B38: 1 | C38: 2026-07-03 | E38: Rj Kanierra | F38: Congo (Republic) | G38: African | H38: Universal Music Group, Sony Music Entertainment | I38: 7571 | J38: 72290 | K38: 56112 | L38: 7294989 | M38: 127002 | N38: 118954 | O38: 4806 | P38: 611000 | Q38: 120666234 | R38: 668379 | S38: 3521 | T38: 1529008 | U38: 242247 | V38: 508599 | W38: 595 | X38: N/A | Y38: 39534 | Z38: N/A | AA38: N/A | AB38: N/A | AC38: N/A | AD38: N/A
A39: =_xlfn.XLOOKUP(E39,Lookups!$E:$E,Lookups!$F:$F,0) -> 1 | B39: 1 | C39: 2026-07-03 | E39: Thatohatsi | F39: South Africa | G39: Electronic | H39: Big Indie Labels, Sony Music Entertainment, Universal Music Group | I39: 7724 | J39: 8494 | K39: 398249 | L39: 233409823 | M39: 2061888 | N39: 4716834 | O39: 138786 | P39: 3740 | Q39: 230529 | R39: 3367 | S39: 58607 | T39: 521500 | U39: 3693 | V39: 11686 | W39: 1038 | X39: N/A | Y39: 139241 | Z39: 7815 | AA39: 167 | AB39: 0 | AC39: 0 | AD39: 259.77235
A40: =_xlfn.XLOOKUP(E40,Lookups!$E:$E,Lookups!$F:$F,0) -> 1 | B40: 1 | C40: 2026-07-03 | E40: Daliwonga | F40: South Africa | G40: Electronic | H40: Big Indie Labels, Sony Music Entertainment, Universal Music Group | I40: 7859 | J40: 11137 | K40: 1535855 | L40: 209306995 | M40: 562917 | N40: 1978790 | O40: 13295 | P40: 264000 | Q40: 160241814 | R40: 1055487 | S40: 10479 | T40: 24203 | U40: 1024613 | V40: 2019252 | W40: 34506 | X40: N/A | Y40: 34748 | Z40: 13060 | AA40: 157 | AB40: 1 | AC40: 14 | AD40: 277.99187
...

Sheet Streaming Data (2024-2026)
A1: Year | B1: Month | C1: <<>> | D1: Artist | E1: Date | F1: Total Spotify Followers | G1: Spotify Followers Change | H1: Total Spotify Streams | I1: Spotify Streams Change | J1: Total Spotify Monthly Listeners | K1: Spotify Monthly Listeners Change | L1: Total TikTok Followers | M1: TikTok Followers Change | N1: Total TikTok Likes | O1: TikTok Likes Change | P1: Total YouTube Subscribers | Q1: YouTube Subscribers Change | R1: Total YouTube Video Views | S1: YouTube Video Views Change | T1: Total Instagram Followers | U1: Instagram Followers Change | V1: Instagram Likes | W1: Total Airplay Spins | X1: Airplay Spins Change | Y1: Total Shazams | Z1: Shazams Change | AA1: Total Facebook Followers | AB1: Facebook Followers Change | AC1: Total SoundCloud Followers | AD1: SoundCloud Followers Change | AE1: Total SoundCloud Plays | AF1: SoundCloud Plays Change | AG1: Total Deezer Followers | AH1: Deezer Followers Change
A2: =YEAR(E2) -> 2024 | B2: =MONTH(E2) -> 7 | D2: Kabza De Small | E2: 2024-07-01 | F2: 3943718 | G2: 140077 | H2: 505367451 | I2: 21673764 | J2: 2333784 | K2: 182763 | L2: 372700 | M2: 8900 | N2: 280100 | O2: 4200 | P2: 60900 | Q2: 0 | R2: 335331667 | S2: 8542027 | T2: 2708658 | U2: 61564 | V2: 792000 | W2: 29262 | X2: 1316 | Y2: N/A | Z2: N/A | AA2: 2002234 | AB2: 4965 | AC2: 21773 | AD2: 196 | AE2: N/A | AF2: N/A | AG2: 212779 | AH2: 550
A3: =YEAR(E3) -> 2024 | B3: =MONTH(E3) -> 8 | D3: Kabza De Small | E3: 2024-08-01 | F3: 4127443 | G3: 183725 | H3: 526843061 | I3: 21244619 | J3: 2250150 | K3: -83634 | L3: 379000 | M3: 6300 | N3: 283100 | O3: 3000 | P3: 60800 | Q3: -100 | R3: 342904757 | S3: 7573090 | T3: 2731941 | U3: 23283 | V3: 405000 | W3: 30451 | X3: 1189 | Y3: N/A | Z3: N/A | AA3: 2002830 | AB3: 596 | AC3: 21926 | AD3: 153 | AE3: N/A | AF3: N/A | AG3: 213294 | AH3: 515
A4: =YEAR(E4) -> 2024 | B4: =MONTH(E4) -> 9 | D4: Kabza De Small | E4: 2024-09-01 | F4: 4372153 | G4: 244710 | H4: 547725136 | I4: 20684894 | J4: 2299229 | K4: 49079 | L4: 384700 | M4: 5700 | N4: 285500 | O4: 2400 | P4: 60800 | Q4: 0 | R4: 351402707 | S4: 8497951 | T4: 2744429 | U4: 12488 | V4: 149000 | W4: 31695 | X4: 1244 | Y4: N/A | Z4: N/A | AA4: 2003989 | AB4: 1159 | AC4: 22080 | AD4: 154 | AE4: N/A | AF4: N/A | AG4: 213834 | AH4: 540
A5: =YEAR(E5) -> 2024 | B5: =MONTH(E5) -> 10 | D5: Kabza De Small | E5: 2024-10-01 | F5: 4588310 | G5: 216157 | H5: 568595248 | I5: 20477035 | J5: 2291205 | K5: -8024 | L5: 387840 | M5: 3140 | N5: 285500 | O5: 0 | P5: 60800 | Q5: 0 | R5: 359187005 | S5: 7784298 | T5: 2787904 | U5: 43475 | V5: 195552 | W5: 33004 | X5: 1309 | Y5: N/A | Z5: N/A | AA5: 2006996 | AB5: 3007 | AC5: 22169 | AD5: 89 | AE5: N/A | AF5: N/A | AG5: 214307 | AH5: 473
A6: =YEAR(E6) -> 2024 | B6: =MONTH(E6) -> 11 | D6: Kabza De Small | E6: 2024-11-01 | F6: 4782667 | G6: 194357 | H6: 590437778 | I6: 21316090 | J6: 2355684 | K6: 64479 | L6: 398750 | M6: 10910 | N6: 285500 | O6: 0 | P6: 300000 | Q6: 239200 | R6: 367357077 | S6: 7985247 | T6: 2814694 | U6: 26790 | V6: 558243 | W6: 34450 | X6: 1446 | Y6: N/A | Z6: N/A | AA6: 2010197 | AB6: 3201 | AC6: 22265 | AD6: 96 | AE6: 500547 | AF6: 255 | AG6: 214836 | AH6: 529
A7: =YEAR(E7) -> 2024 | B7: =MONTH(E7) -> 12 | D7: Kabza De Small | E7: 2024-12-01 | F7: 4993026 | G7: 210359 | H7: 614900690 | I7: 24191321 | J7: 2633727 | K7: 278043 | L7: 404700 | M7: 5950 | N7: 295700 | O7: 10200 | P7: 325000 | Q7: 25000 | R7: 377085048 | S7: 9727971 | T7: 2843408 | U7: 28714 | V7: 413466 | W7: 35805 | X7: 1355 | Y7: N/A | Z7: N/A | AA7: 2016647 | AB7: 6450 | AC7: 22345 | AD7: 80 | AE7: 507420 | AF7: 6873 | AG7: 215431 | AH7: 595
A8: =YEAR(E8) -> 2025 | B8: =MONTH(E8) -> 1 | D8: Kabza De Small | E8: 2025-01-01 | F8: 5222714 | G8: 229688 | H8: 643747228 | I8: 28325229 | J8: 3088574 | K8: 454847 | L8: 408700 | M8: 4000 | N8: 297200 | O8: 1500 | P8: 350000 | Q8: 25000 | R8: 388456111 | S8: 11310425 | T8: 2869736 | U8: 26328 | V8: 353867 | W8: 37226 | X8: 1421 | Y8: N/A | Z8: N/A | AA8: 2019042 | AB8: 2395 | AC8: 22416 | AD8: 71 | AE8: 515239 | AF8: 7584 | AG8: 216084 | AH8: 653
A9: =YEAR(E9) -> 2025 | B9: =MONTH(E9) -> 2 | D9: Kabza De Small | E9: 2025-02-01 | F9: 5387842 | G9: 165128 | H9: 664769093 | I9: 21021865 | J9: 2419870 | K9: -668704 | L9: 408700 | M9: 0 | N9: 297200 | O9: 0 | P9: 363000 | Q9: 13000 | R9: 395696594 | S9: 7240483 | T9: 2884863 | U9: 15127 | V9: 177250 | W9: 38623 | X9: 1397 | Y9: N/A | Z9: N/A | AA9: 2019410 | AB9: 368 | AC9: 22495 | AD9: 79 | AE9: 523021 | AF9: 7782 | AG9: 216569 | AH9: 485
A10: =YEAR(E10) -> 2025 | B10: =MONTH(E10) -> 3 | D10: Kabza De Small | E10: 2025-03-01 | F10: 5522544 | G10: 134702 | H10: 682413795 | I10: 17612200 | J10: 2368723 | K10: -51147 | L10: 408700 | M10: 0 | N10: 297200 | O10: 0 | P10: 374000 | Q10: 11000 | R10: 402522248 | S10: 6825654 | T10: 2897550 | U10: 12687 | V10: 193124 | W10: 39828 | X10: 1205 | Y10: N/A | Z10: N/A | AA10: 2020778 | AB10: 1368 | AC10: 22554 | AD10: 59 | AE10: 529810 | AF10: 6789 | AG10: 216946 | AH10: 377
A11: =YEAR(E11) -> 2025 | B11: =MONTH(E11) -> 4 | D11: Kabza De Small | E11: 2025-04-01 | F11: 5657707 | G11: 135163 | H11: 702950129 | I11: 20209966 | J11: 2397713 | K11: 28990 | L11: 408700 | M11: 0 | N11: 297200 | O11: 0 | P11: 388000 | Q11: 14000 | R11: 410289157 | S11: 7766909 | T11: 2928569 | U11: 31019 | V11: 747585 | W11: 41146 | X11: 1318 | Y11: N/A | Z11: N/A | AA11: 2024156 | AB11: 3378 | AC11: 22637 | AD11: 83 | AE11: 537807 | AF11: 7997 | AG11: 217610 | AH11: 664
A12: =YEAR(E12) -> 2025 | B12: =MONTH(E12) -> 5 | D12: Kabza De Small | E12: 2025-05-01 | F12: 5819145 | G12: 161438 | H12: 723180977 | I12: 19987562 | J12: 2514876 | K12: 117163 | L12: 408700 | M12: 0 | N12: 297200 | O12: 0 | P12: 405000 | Q12: 17000 | R12: 417746817 | S12: 7274514 | T12: 2948624 | U12: 20055 | V12: 433878 | W12: 42245 | X12: 1099 | Y12: N/A | Z12: N/A | AA12: 2021947 | AB12: -2209 | AC12: 22711 | AD12: 74 | AE12: 545554 | AF12: 7747 | AG12: 218071 | AH12: 461
A13: =YEAR(E13) -> 2025 | B13: =MONTH(E13) -> 6 | D13: Kabza De Small | E13: 2025-06-01 | F13: 5968283 | G13: 149138 | H13: 747253152 | I13: 23979228 | J13: 2632370 | K13: 117494 | L13: 408700 | M13: 0 | N13: 297200 | O13: 0 | P13: 418000 | Q13: 13000 | R13: 425396293 | S13: 7639777 | T13: 2965004 | U13: 16380 | V13: 192416 | W13: 46424 | X13: 4179 | Y13: N/A | Z13: N/A | AA13: 2023045 | AB13: 1098 | AC13: 22799 | AD13: 88 | AE13: 554727 | AF13: 9173 | AG13: 218541 | AH13: 470
A14: =YEAR(E14) -> 2025 | B14: =MONTH(E14) -> 7 | D14: Kabza De Small | E14: 2025-07-01 | F14: 6073080 | G14: 104797 | H14: 770682482 | I14: 22966695 | J14: 2812208 | K14: 179838 | L14: 425920 | M14: 17220 | N14: 304020 | O14: 6820 | P14: 435000 | Q14: 17000 | R14: 432626415 | S14: 7227565 | T14: 2989468 | U14: 24464 | V14: 463424 | W14: 51197 | X14: 4773 | Y14: N/A | Z14: N/A | AA14: 2023387 | AB14: 342 | AC14: 22876 | AD14: 77 | AE14: 562851 | AF14: 8064 | AG14: 219102 | AH14: 561
A15: =YEAR(E15) -> 2025 | B15: =MONTH(E15) -> 8 | D15: Kabza De Small | E15: 2025-08-01 | F15: 6219373 | G15: 146293 | H15: 806892490 | I15: 32841299 | J15: 3271805 | K15: 459597 | L15: 432400 | M15: 6480 | N15: 309300 | O15: 5280 | P15: 462000 | Q15: 27000 | R15: 439676480 | S15: 7038938 | T15: 3029699 | U15: 40231 | V15: 729772 | W15: 56088 | X15: 4891 | Y15: N/A | Z15: N/A | AA15: 2033791 | AB15: 10404 | AC15: 22961 | AD15: 85 | AE15: 571123 | AF15: 8034 | AG15: 219810 | AH15: 708
A16: =YEAR(E16) -> 2025 | B16: =MONTH(E16) -> 9 | D16: Kabza De Small | E16: 2025-09-01 | F16: 6372718 | G16: 153345 | H16: 845746693 | I16: 38665680 | J16: 3375181 | K16: 103376 | L16: 438000 | M16: 5600 | N16: 314700 | O16: 5400 | P16: 482000 | Q16: 20000 | R16: 447075977 | S16: 7391766 | T16: 3047626 | U16: 17927 | V16: 807527 | W16: 61720 | X16: 5632 | Y16: N/A | Z16: N/A | AA16: 2049234 | AB16: 15443 | AC16: 23060 | AD16: 99 | AE16: 578998 | AF16: 7875 | AG16: 220493 | AH16: 683
A17: =YEAR(E17) -> 2025 | B17: =MONTH(E17) -> 10 | D17: Kabza De Small | E17: 2025-10-01 | F17: 6524304 | G17: 151586 | H17: 884818101 | I17: 38265832 | J17: 3497866 | K17: 122685 | L17: 441300 | M17: 3300 | N17: 317300 | O17: 2600 | P17: 498000 | Q17: 16000 | R17: 454091682 | S17: 7014415 | T17: 3068902 | U17: 21276 | V17: 116778 | W17: 67374 | X17: 5654 | Y17: N/A | Z17: N/A | AA17: 2063220 | AB17: 13986 | AC17: 23148 | AD17: 88 | AE17: 587216 | AF17: 8218 | AG17: 221066 | AH17: 573
... A22: =YEAR(E22) -> 2026 | B22: =MONTH(E22) -> 3 | D22: Kabza De Small | E22: 2026-03-01 | F22: 7334070 | G22: 137158 | H22: 1034766488 | I22: 22721618 | J22: 3079098 | K22: 42764 | L22: 454020 | M22: 3000 | N22: 326600 | O22: 0 | P22: 551000 | Q22: 8000 | R22: 484538429 | S22: 6155857 | T22: 3134717 | U22: 12550 | V22: 175528 | W22: 88829 | X22: 3958 | Y22: N/A | Z22: N/A | AA22: 2084313 | AB22: 7548 | AC22: 23541 | AD22: 101 | AE22: 620146 | AF22: 7973 | AG22: 223394 | AH22: 370
A23: =YEAR(E23) -> 2026 | B23: =MONTH(E23) -> 4 | D23: Kabza De Small | E23: 2026-04-01 | F23: 7520172 | G23: 186102 | H23: 1062295287 | I23: 27281686 | J23: 3267700 | K23: 188602 | L23: 456970 | M23: 2114 | N23: 334315 | O23: 718 | P23: 563000 | Q23: 12000 | R23: 491867337 | S23: 7328913 | T23: 3148655 | U23: 13938 | V23: 90782 | W23: 93014 | X23: 4185 | Y23: 65425759 | Z23: 637237 | AA23: 2111113 | AB23: 26800 | AC23: 23645 | AD23: 104 | AE23: 626464 | AF23: 6311 | AG23: 223923 | AH23: 529
A24: =YEAR(E24) -> 2026 | B24: =MONTH(E24) -> 5 | D24: Kabza De Small | E24: 2026-05-01 | F24: 7646607 | G24: 126435 | H24: 1087941638 | I24: 25568425 | J24: 3211035 | K24: -56665 | L24: 460320 | M24: 3350 | N24: 337952 | O24: 3637 | P24: 573000 | Q24: 10000 | R24: 499019254 | S24: 7151917 | T24: 3162014 | U24: 13359 | V24: 141073 | W24: 97564 | X24: 4550 | Y24: 65504766 | Z24: 79007 | AA24: 2123312 | AB24: 12199 | AC24: 23743 | AD24: 98 | AE24: 632867 | AF24: 6403 | AG24: 224404 | AH24: 481
A25: =YEAR(E25) -> 2026 | B25: =MONTH(E25) -> 6 | D25: Kabza De Small | E25: 2026-06-01 | F25: 7781089 | G25: 134482 | H25: 1121801331 | I25: 32160407 | J25: 4217498 | K25: 1006463 | L25: 464610 | M25: 4290 | N25: 343264 | O25: 5312 | P25: 584000 | Q25: 11000 | R25: 506579169 | S25: 7559915 | T25: 3147714 | U25: -14300 | V25: 167381 | W25: 102214 | X25: 4650 | Y25: 67284391 | Z25: 1779625 | AA25: 2130400 | AB25: 7088 | AC25: 23813 | AD25: 70 | AE25: 638213 | AF25: 5347 | AG25: 224915 | AH25: 511
A26: =YEAR(E26) -> 2026 | B26: =MONTH(E26) -> 7 | D26: Kabza De Small | E26: 2026-07-01 | F26: 7903606 | G26: 122517 | H26: 1148699708 | I26: 26873378 | J26: 3831583 | K26: -385915 | L26: 466332 | M26: 1722 | N26: 345293 | O26: 2029 | P26: 593000 | Q26: 9000 | R26: 514051287 | S26: 7472119 | T26: 3152533 | U26: 4819 | V26: 178830 | W26: 106230 | X26: 4016 | Y26: 67925845 | Z26: 667039 | AA26: 2130400 | AB26: 0 | AC26: 23876 | AD26: 63 | AE26: 643601 | AF26: 5388 | AG26: 225364 | AH26: 449
A27: =YEAR(E27) -> 2024 | B27: =MONTH(E27) -> 7 | D27: DJ Maphorisa | E27: 2024-07-01 | F27: 2405061 | G27: 49456 | H27: 656914065 | I27: 20908537 | J27: 2624458 | K27: 230878 | L27: 1500000 | M27: 0 | N27: 6100000 | O27: 500000 | P27: 635000 | Q27: 10000 | R27: 594839553 | S27: 8665412 | T27: 3260867 | U27: 31909 | V27: 1175000 | W27: 4310 | X27: 204 | Y27: N/A | Z27: N/A | AA27: 4355081 | AB27: -1107 | AC27: 38838 | AD27: 119 | AE27: N/A | AF27: N/A | AG27: 215753 | AH27: 367
A28: =YEAR(E28) -> 2024 | B28: =MONTH(E28) -> 8 | D28: DJ Maphorisa | E28: 2024-08-01 | F28: 2447753 | G28: 42692 | H28: 681893836 | I28: 24263666 | J28: 2545831 | K28: -78627 | L28: 1600000 | M28: 100000 | N28: 7100000 | O28: 1000000 | P28: 643000 | Q28: 8000 | R28: 603056513 | S28: 8171102 | T28: 3284946 | U28: 24079 | V28: 391000 | W28: 4437 | X28: 127 | Y28: N/A | Z28: N/A | AA28: 4357838 | AB28: 2757 | AC28: 38952 | AD28: 114 | AE28: N/A | AF28: N/A | AG28: 216123 | AH28: 370
A29: =YEAR(E29) -> 2024 | B29: =MONTH(E29) -> 9 | D29: DJ Maphorisa | E29: 2024-09-01 | F29: 2541174 | G29: 93421 | H29: 706979463 | I29: 24965777 | J29: 2577883 | K29: 32052 | L29: 1700000 | M29: 100000 | N29: 7700000 | O29: 600000 | P29: 651000 | Q29: 8000 | R29: 612000872 | S29: 8944359 | T29: 3319476 | U29: 34530 | V29: 616000 | W29: 4535 | X29: 98 | Y29: N/A | Z29: N/A | AA29: 4377242 | AB29: 19404 | AC29: 39075 | AD29: 123 | AE29: N/A | AF29: N/A | AG29: 216518 | AH29: 395
A30: =YEAR(E30) -> 2024 | B30: =MONTH(E30) -> 10 | D30: DJ Maphorisa | E30: 2024-10-01 | F30: 2621909 | G30: 80735 | H30: 731369104 | I30: 23933635 | J30: 2627627 | K30: 49744 | L30: 1700000 | M30: 0 | N30: 7800000 | O30: 100000 | P30: 659000 | Q30: 8000 | R30: 620914397 | S30: 8913525 | T30: 3366007 | U30: 46531 | V30: 50238 | W30: 4674 | X30: 139 | Y30: N/A | Z30: N/A | AA30: 4413025 | AB30: 35783 | AC30: 39177 | AD30: 102 | AE30: N/A | AF30: N/A | AG30: 216897 | AH30: 379
A31: =YEAR(E31) -> 2024 | B31: =MONTH(E31) -> 11 | D31: DJ Maphorisa | E31: 2024-11-01 | F31: 2662018 | G31: 40109 | H31: 756164146 | I31: 24443697 | J31: 2704198 | K31: 76571 | L31: 1760000 | M31: 60000 | N31: 7800000 | O31: 0 | P31: 666000 | Q31: 7000 | R31: 629457436 | S31: 8543039 | T31: 3384767 | U31: 18760 | V31: 383875 | W31: 4794 | X31: 120 | Y31: N/A | Z31: N/A | AA31: 4413493 | AB31: 468 | AC31: 39277 | AD31: 100 | AE31: 5554464 | AF31: 564 | AG31: 217307 | AH31: 410
A32: =YEAR(E32) -> 2024 | B32: =MONTH(E32) -> 12 | D32: DJ Maphorisa | E32: 2024-12-01 | F32: 2708797 | G32: 46779 | H32: 786515553 | I32: 29917017 | J32: 2931422 | K32: 227224 | L32: 1800000 | M32: 40000 | N32: 8900000 | O32: 1100000 | P32: 693000 | Q32: 27000 | R32: 641883773 | S32: 11992335 | T32: 3407234 | U32: 22467 | V32: 307733 | W32: 4916 | X32: 122 | Y32: N/A | Z32: N/A | AA32: 4424809 | AB32: 11316 | AC32: 39383 | AD32: 106 | AE32: 5571785 | AF32: 17321 | AG32: 217769 | AH32: 462
A33: =YEAR(E33) -> 2025 | B33: =MONTH(E33) -> 1 | D33: DJ Maphorisa | E33: 2025-01-01 | F33: 2771816 | G33: 63019 | H33: 827251443 | I33: 40299124 | J33: 3572918 | K33: 641496 | L33: 1800000 | M33: 0 | N33: 9100000 | O33: 200000 | P33: 736000 | Q33: 43000 | R33: 659449218 | S33: 17565445 | T33: 3427759 | U33: 20525 | V33: 343951 | W33: 5024 | X33: 108 | Y33: N/A | Z33: N/A | AA33: 4451986 | AB33: 27177 | AC33: 39498 | AD33: 115 | AE33: 5590126 | AF33: 18341 | AG33: 218329 | AH33: 560
A34: =YEAR(E34) -> 2025 | B34: =MONTH(E34) -> 2 | D34: DJ Maphorisa | E34: 2025-02-01 | F34: 2821351 | G34: 49535 | H34: 856582922 | I34: 29331557 | J34: 2774789 | K34: -798129 | L34: 1840000 | M34: 40000 | N34: 9540000 | O34: 440000 | P34: 779000 | Q34: 43000 | R34: 675765340 | S34: 16316122 | T34: 3454163 | U34: 26404 | V34: 722360 | W34: 5122 | X34: 98 | Y34: N/A | Z34: N/A | AA34: 4480162 | AB34: 28176 | AC34: 39616 | AD34: 118 | AE34: 5607808 | AF34: 17682 | AG34: 218770 | AH34: 441
A35: =YEAR(E35) -> 2025 | B35: =MONTH(E35) -> 3 | D35: DJ Maphorisa | E35: 2025-03-01 | F35: 2868573 | G35: 47222 | H35: 883686152 | I35: 26777718 | J35: 3029601 | K35: 254812 | L35: 1840000 | M35: 0 | N35: 9540000 | O35: 0 | P35: 836000 | Q35: 57000 | R35: 697553956 | S35: 21193066 | T35: 3465384 | U35: 11221 | V35: 257505 | W35: 5197 | X35: 75 | Y35: N/A | Z35: N/A | AA35: 4482978 | AB35: 2816 | AC35: 39731 | AD35: 115 | AE35: 5624033 | AF35: 16131 | AG35: 219086 | AH35: 316
A36: =YEAR(E36) -> 2025 | B36: =MONTH(E36) -> 4 | D36: DJ Maphorisa | E36: 2025-04-01 | F36: 2915282 | G36: 46709 | H36: 915573739 | I36: 30576808 | J36: 3311287 | K36: 281686 | L36: 1840000 | M36: 0 | N36: 9540000 | O36: 0 | P36: 894000 | Q36: 58000 | R36: 719795809 | S36: 21805650 | T36: 3468796 | U36: 3412 | V36: 321530 | W36: 5265 | X36: 68 | Y36: N/A | Z36: N/A | AA36: 4490262 | AB36: 7284 | AC36: 39872 | AD36: 141 | AE36: 5642150 | AF36: 17724 | AG36: 219717 | AH36: 631
A37: =YEAR(E37) -> 2025 | B37: =MONTH(E37) -> 5 | D37: DJ Maphorisa | E37: 2025-05-01 | F37: 2978428 | G37: 63146 | H37: 949780533 | I37: 34110636 | J37: 3463175 | K37: 151888 | L37: 1840000 | M37: 0 | N37: 9540000 | O37: 0 | P37: 954000 | Q37: 60000 | R37: 741653373 | S37: 21837172 | T37: 3473592 | U37: 4796 | V37: 291857 | W37: 5327 | X37: 62 | Y37: N/A | Z37: N/A | AA37: 4492236 | AB37: 1974 | AC37: 40040 | AD37: 168 | AE37: 5660744 | AF37: 18589 | AG37: 220138 | AH37: 421
A38: =YEAR(E38) -> 2025 | B38: =MONTH(E38) -> 6 | D38: DJ Maphorisa | E38: 2025-06-01 | F38: 3037394 | G38: 58966 | H38: 984536074 | I38: 34619866 | J38: 3433738 | K38: -29437 | L38: 1840000 | M38: 0 | N38: 9540000 | O38: 0 | P38: 1000000 | Q38: 46000 | R38: 759614400 | S38: 17955254 | T38: 3481607 | U38: 8015 | V38: 190547 | W38: 6451 | X38: 1124 | Y38: N/A | Z38: N/A | AA38: 4495813 | AB38: 3577 | AC38: 40170 | AD38: 130 | AE38: 5680946 | AF38: 20201 | AG38: 220573 | AH38: 435
A39: =YEAR(E39) -> 2025 | B39: =MONTH(E39) -> 7 | D39: DJ Maphorisa | E39: 2025-07-01 | F39: 3113325 | G39: 75931 | H39: 1015338775 | I39: 30723975 | J39: 3515461 | K39: 81723 | L39: 2020000 | M39: 180000 | N39: 11920000 | O39: 2380000 | P39: 1040000 | Q39: 40000 | R39: 776839652 | S39: 17216620 | T39: 3488933 | U39: 7326 | V39: 180987 | W39: 7964 | X39: 1513 | Y39: N/A | Z39: N/A | AA39: 4495139 | AB39: -674 | AC39: 40293 | AD39: 123 | AE39: 5699570 | AF39: 18624 | AG39: 221116 | AH39: 543
A40: =YEAR(E40) -> 2025 | B40: =MONTH(E40) -> 8 | D40: DJ Maphorisa | E40: 2025-08-01 | F40: 3205657 | G40: 92332 | H40: 1051342700 | I40: 35670325 | J40: 3671315 | K40: 155854 | L40: 2100000 | M40: 80000 | N40: 14200000 | O40: 2280000 | P40: 1080000 | Q40: 40000 | R40: 793010580 | S40: 15998864 | T40: 3505744 | U40: 16811 | V40: 641992 | W40: 9379 | X40: 1415 | Y40: N/A | Z40: N/A | AA40: 4497678 | AB40: 2539 | AC40: 40438 | AD40: 145 | AE40: 5719328 | AF40: 19758 | AG40: 221761 | AH40: 645
A41: =YEAR(E41) -> 2025 | B41: =MONTH(E41) -> 9 | D41: DJ Maphorisa | E41: 2025-09-01 | F41: 3317371 | G41: 111714 | H41: 1085492942 | I41: 33582078 | J41: 3955627 | K41: 284312 | L41: 2200000 | M41: 100000 | N41: 15300000 | O41: 1100000 | P41: 1210000 | Q41: 130000 | R41: 810456354 | S41: 17141301 | T41: 3535093 | U41: 29349 | V41: 492528 | W41: 11077 | X41: 1698 | Y41: N/A | Z41: N/A | AA41: 4507480 | AB41: 9802 | AC41: 40574 | AD41: 136 | AE41: 5738839 | AF41: 19511 | AG41: 222332 | AH41: 571
A42: =YEAR(E42) -> 2025 | B42: =MONTH(E42) -> 10 | D42: DJ Maphorisa | E42: 2025-10-01 | F42: 3442852 | G42: 125481 | H42: 1125735915 | I42: 39494590 | J42: 3947710 | K42: -7917 | L42: 2300000 | M42: 100000 | N42: 16600000 | O42: 1300000 | P42: 1250000 | Q42: 40000 | R42: 826909470 | S42: 16445418 | T42: 3594944 | U42: 59851 | V42: 270424 | W42: 12547 | X42: 1470 | Y42: N/A | Z42: N/A | AA42: 4511759 | AB42: 4279 | AC42: 40688 | AD42: 114 | AE42: 5756807 | AF42: 17968 | AG42: 222789 | AH42: 457
... A47: =YEAR(E47) -> 2026 | B47: =MONTH(E47) -> 3 | D47: DJ Maphorisa | E47: 2026-03-01 | F47: 4056869 | G47: 79407 | H47: 1328133349 | I47: 31379329 | J47: 4893966 | K47: -130466 | L47: 2330000 | M47: 0 | N47: 17900000 | O47: 0 | P47: 1370000 | Q47: 20000 | R47: 908735145 | S47: 13855993 | T47: 3728962 | U47: 17828 | V47: 174320 | W47: 19573 | X47: 1496 | Y47: N/A | Z47: N/A | AA47: 4620784 | AB47: 8576 | AC47: 41249 | AD47: 106 | AE47: 5853514 | AF47: 21494 | AG47: 224755 | AH47: 346
A48: =YEAR(E48) -> 2026 | B48: =MONTH(E48) -> 4 | D48: DJ Maphorisa | E48: 2026-04-01 | F48: 4198055 | G48: 141186 | H48: 1362692089 | I48: 34575552 | J48: 4876913 | K48: -17053 | L48: 2341654 | M48: 10919 | N48: 18754553 | O48: 45586 | P48: 1380000 | Q48: 10000 | R48: 923800761 | S48: 15065638 | T48: 3748837 | U48: 19875 | V48: 138273 | W48: 21123 | X48: 1550 | Y48: 78933612 | Z48: 593440 | AA48: 4628907 | AB48: 8123 | AC48: 41354 | AD48: 105 | AE48: 5871423 | AF48: 17909 | AG48: 225172 | AH48: 417
...

Sheet The Piano Index (Weekly)
C2: Select Week: | D2: 1
C3: Current | I3: Growth Analysis
C4: Artist | D4: Total Spotify Followers | E4: Total Streams | F4: Monthly Listeners | G4: Listener-Follower Ratio | I4: Week | J4: Total Spotify Followers | K4: Growth WoW
C5: Uncool MC | D5: =SUMIFS('Artist Profile Data (Weekly)'!$K:$K,'Artist Profile Data (Weekly)'!$E:$E,$C5,'Artist Profile Data (Weekly)'!$B:$B,$D$2) -> 79136 | E5: =SUMIFS('Artist Profile Data (Weekly)'!$L:$L,'Artist Profile Data (Weekly)'!$E:$E,$C5,'Artist Profile Data (Weekly)'!$B:$B,$D$2) -> 150403474 | F5: =SUMIFS('Artist Profile Data (Weekly)'!$M:$M,'Artist Profile Data (Weekly)'!$E:$E,$C5,'Artist Profile Data (Weekly)'!$B:$B,D$2) -> 1515723 | G5: =IFERROR(F5/D5,0) -> 19.153394 | I5: 1 | J5: =SUMIFS('Artist Profile Data (Weekly)'!$K:$K,'Artist Profile Data (Weekly)'!$A:$A,1,'Artist Profile Data (Weekly)'!$B:$B,$I5) -> 36070934
C6: TxC | D6: =SUMIFS('Artist Profile Data (Weekly)'!$K:$K,'Artist Profile Data (Weekly)'!$E:$E,$C6,'Artist Profile Data (Weekly)'!$B:$B,$D$2) -> 318313 | E6: =SUMIFS('Artist Profile Data (Weekly)'!$L:$L,'Artist Profile Data (Weekly)'!$E:$E,$C6,'Artist Profile Data (Weekly)'!$B:$B,$D$2) -> 98169042 | F6: =SUMIFS('Artist Profile Data (Weekly)'!$M:$M,'Artist Profile Data (Weekly)'!$E:$E,$C6,'Artist Profile Data (Weekly)'!$B:$B,D$2) -> 1995769 | G6: =IFERROR(F6/D6,0) -> 6.2698319 | I6: 2 | J6: =SUMIFS('Artist Profile Data (Weekly)'!$K:$K,'Artist Profile Data (Weekly)'!$A:$A,1,'Artist Profile Data (Weekly)'!$B:$B,$I6) -> 0 | K6: =IFERROR((J6-J5)/J5,0) -> -1
C7: Royal Musiq | D7: =SUMIFS('Artist Profile Data (Weekly)'!$K:$K,'Artist Profile Data (Weekly)'!$E:$E,$C7,'Artist Profile Data (Weekly)'!$B:$B,$D$2) -> 257831 | E7: =SUMIFS('Artist Profile Data (Weekly)'!$L:$L,'Artist Profile Data (Weekly)'!$E:$E,$C7,'Artist Profile Data (Weekly)'!$B:$B,$D$2) -> 127394961 | F7: =SUMIFS('Artist Profile Data (Weekly)'!$M:$M,'Artist Profile Data (Weekly)'!$E:$E,$C7,'Artist Profile Data (Weekly)'!$B:$B,D$2) -> 1603306 | G7: =IFERROR(F7/D7,0) -> 6.2184377 | I7: 3 | J7: =SUMIFS('Artist Profile Data (Weekly)'!$K:$K,'Artist Profile Data (Weekly)'!$A:$A,1,'Artist Profile Data (Weekly)'!$B:$B,$I7) -> 0 | K7: =IFERROR((J7-J6)/J6,0) -> 0
C8: Thatohatsi | D8: =SUMIFS('Artist Profile Data (Weekly)'!$K:$K,'Artist Profile Data (Weekly)'!$E:$E,$C8,'Artist Profile Data (Weekly)'!$B:$B,$D$2) -> 398249 | E8: =SUMIFS('Artist Profile Data (Weekly)'!$L:$L,'Artist Profile Data (Weekly)'!$E:$E,$C8,'Artist Profile Data (Weekly)'!$B:$B,$D$2) -> 233409823 | F8: =SUMIFS('Artist Profile Data (Weekly)'!$M:$M,'Artist Profile Data (Weekly)'!$E:$E,$C8,'Artist Profile Data (Weekly)'!$B:$B,D$2) -> 2061888 | G8: =IFERROR(F8/D8,0) -> 5.177384 | I8: 4 | J8: =SUMIFS('Artist Profile Data (Weekly)'!$K:$K,'Artist Profile Data (Weekly)'!$A:$A,1,'Artist Profile Data (Weekly)'!$B:$B,$I8) -> 0 | K8: =IFERROR((J8-J7)/J7,0) -> 0
C9: XDuppy | D9: =SUMIFS('Artist Profile Data (Weekly)'!$K:$K,'Artist Profile Data (Weekly)'!$E:$E,$C9,'Artist Profile Data (Weekly)'!$B:$B,$D$2) -> 492332 | E9: =SUMIFS('Artist Profile Data (Weekly)'!$L:$L,'Artist Profile Data (Weekly)'!$E:$E,$C9,'Artist Profile Data (Weekly)'!$B:$B,$D$2) -> 286861518 | F9: =SUMIFS('Artist Profile Data (Weekly)'!$M:$M,'Artist Profile Data (Weekly)'!$E:$E,$C9,'Artist Profile Data (Weekly)'!$B:$B,D$2) -> 2277376 | G9: =IFERROR(F9/D9,0) -> 4.6256916 | I9: 5 | J9: =SUMIFS('Artist Profile Data (Weekly)'!$K:$K,'Artist Profile Data (Weekly)'!$A:$A,1,'Artist Profile Data (Weekly)'!$B:$B,$I9) -> 0 | K9: =IFERROR((J9-J8)/J8,0) -> 0
C10: Justin99 | D10: =SUMIFS('Artist Profile Data (Weekly)'!$K:$K,'Artist Profile Data (Weekly)'!$E:$E,$C10,'Artist Profile Data (Weekly)'!$B:$B,$D$2) -> 439698 | E10: =SUMIFS('Artist Profile Data (Weekly)'!$L:$L,'Artist Profile Data (Weekly)'!$E:$E,$C10,'Artist Profile Data (Weekly)'!$B:$B,$D$2) -> 91714661 | F10: =SUMIFS('Artist Profile Data (Weekly)'!$M:$M,'Artist Profile Data (Weekly)'!$E:$E,$C10,'Artist Profile Data (Weekly)'!$B:$B,D$2) -> 800754 | G10: =IFERROR(F10/D10,0) -> 1.8211454 | I10: 6 | J10: =SUMIFS('Artist Profile Data (Weekly)'!$K:$K,'Artist Profile Data (Weekly)'!$A:$A,1,'Artist Profile Data (Weekly)'!$B:$B,$I10) -> 0 | K10: =IFERROR((J10-J9)/J9,0) -> 0
C11: Focalistic | D11: =SUMIFS('Artist Profile Data (Weekly)'!$K:$K,'Artist Profile Data (Weekly)'!$E:$E,$C11,'Artist Profile Data (Weekly)'!$B:$B,$D$2) -> 1570892 | E11: =SUMIFS('Artist Profile Data (Weekly)'!$L:$L,'Artist Profile Data (Weekly)'!$E:$E,$C11,'Artist Profile Data (Weekly)'!$B:$B,$D$2) -> 386533451 | F11: =SUMIFS('Artist Profile Data (Weekly)'!$M:$M,'Artist Profile Data (Weekly)'!$E:$E,$C11,'Artist Profile Data (Weekly)'!$B:$B,D$2) -> 2458020 | G11: =IFERROR(F11/D11,0) -> 1.5647288 | I11: 7 | J11: =SUMIFS('Artist Profile Data (Weekly)'!$K:$K,'Artist Profile Data (Weekly)'!$A:$A,1,'Artist Profile Data (Weekly)'!$B:$B,$I11) -> 0 | K11: =IFERROR((J11-J10)/J10,0) -> 0
C12: Scotts Maphuma | D12: =SUMIFS('Artist Profile Data (Weekly)'!$K:$K,'Artist Profile Data (Weekly)'!$E:$E,$C12,'Artist Profile Data (Weekly)'!$B:$B,$D$2) -> 1838533 | E12: =SUMIFS('Artist Profile Data (Weekly)'!$L:$L,'Artist Profile Data (Weekly)'!$E:$E,$C12,'Artist Profile Data (Weekly)'!$B:$B,$D$2) -> 461935885 | F12: =SUMIFS('Artist Profile Data (Weekly)'!$M:$M,'Artist Profile Data (Weekly)'!$E:$E,$C12,'Artist Profile Data (Weekly)'!$B:$B,D$2) -> 2823644 | G12: =IFERROR(F12/D12,0) -> 1.5358136 | I12: 8 | J12: =SUMIFS('Artist Profile Data (Weekly)'!$K:$K,'Artist Profile Data (Weekly)'!$A:$A,1,'Artist Profile Data (Weekly)'!$B:$B,$I12) -> 0 | K12: =IFERROR((J12-J11)/J11,0) -> 0
C13: Tyler ICU | D13: =SUMIFS('Artist Profile Data (Weekly)'!$K:$K,'Artist Profile Data (Weekly)'!$E:$E,$C13,'Artist Profile Data (Weekly)'!$B:$B,$D$2) -> 1551136 | E13: =SUMIFS('Artist Profile Data (Weekly)'!$L:$L,'Artist Profile Data (Weekly)'!$E:$E,$C13,'Artist Profile Data (Weekly)'!$B:$B,$D$2) -> 420009551 | F13: =SUMIFS('Artist Profile Data (Weekly)'!$M:$M,'Artist Profile Data (Weekly)'!$E:$E,$C13,'Artist Profile Data (Weekly)'!$B:$B,D$2) -> 2278538 | G13: =IFERROR(F13/D13,0) -> 1.4689479 | I13: 9 | J13: =SUMIFS('Artist Profile Data (Weekly)'!$K:$K,'Artist Profile Data (Weekly)'!$A:$A,1,'Artist Profile Data (Weekly)'!$B:$B,$I13) -> 0 | K13: =IFERROR((J13-J12)/J12,0) -> 0
C14: Sam Deep | D14: =SUMIFS('Artist Profile Data (Weekly)'!$K:$K,'Artist Profile Data (Weekly)'!$E:$E,$C14,'Artist Profile Data (Weekly)'!$B:$B,$D$2) -> 1275926 | E14: =SUMIFS('Artist Profile Data (Weekly)'!$L:$L,'Artist Profile Data (Weekly)'!$E:$E,$C14,'Artist Profile Data (Weekly)'!$B:$B,$D$2) -> 186616030 | F14: =SUMIFS('Artist Profile Data (Weekly)'!$M:$M,'Artist Profile Data (Weekly)'!$E:$E,$C14,'Artist Profile Data (Weekly)'!$B:$B,D$2) -> 1685783 | G14: =IFERROR(F14/D14,0) -> 1.3212232 | I14: 10 | J14: =SUMIFS('Artist Profile Data (Weekly)'!$K:$K,'Artist Profile Data (Weekly)'!$A:$A,1,'Artist Profile Data (Weekly)'!$B:$B,$I14) -> 0 | K14: =IFERROR((J14-J13)/J13,0) -> 0
C15: Pcee | D15: =SUMIFS('Artist Profile Data (Weekly)'!$K:$K,'Artist Profile Data (Weekly)'!$E:$E,$C15,'Artist Profile Data (Weekly)'!$B:$B,$D$2) -> 802995 | E15: =SUMIFS('Artist Profile Data (Weekly)'!$L:$L,'Artist Profile Data (Weekly)'!$E:$E,$C15,'Artist Profile Data (Weekly)'!$B:$B,$D$2) -> 198722502 | F15: =SUMIFS('Artist Profile Data (Weekly)'!$M:$M,'Artist Profile Data (Weekly)'!$E:$E,$C15,'Artist Profile Data (Weekly)'!$B:$B,D$2) -> 993429 | G15: =IFERROR(F15/D15,0) -> 1.2371547 | I15: 11 | J15: =SUMIFS('Artist Profile Data (Weekly)'!$K:$K,'Artist Profile Data (Weekly)'!$A:$A,1,'Artist Profile Data (Weekly)'!$B:$B,$I15) -> 0 | K15: =IFERROR((J15-J14)/J14,0) -> 0
C16: Zee Nxumalo | D16: =SUMIFS('Artist Profile Data (Weekly)'!$K:$K,'Artist Profile Data (Weekly)'!$E:$E,$C16,'Artist Profile Data (Weekly)'!$B:$B,$D$2) -> 1693660 | E16: =SUMIFS('Artist Profile Data (Weekly)'!$L:$L,'Artist Profile Data (Weekly)'!$E:$E,$C16,'Artist Profile Data (Weekly)'!$B:$B,$D$2) -> 271735115 | F16: =SUMIFS('Artist Profile Data (Weekly)'!$M:$M,'Artist Profile Data (Weekly)'!$E:$E,$C16,'Artist Profile Data (Weekly)'!$B:$B,D$2) -> 2017591 | G16: =IFERROR(F16/D16,0) -> 1.1912609 | I16: 12 | J16: =SUMIFS('Artist Profile Data (Weekly)'!$K:$K,'Artist Profile Data (Weekly)'!$A:$A,1,'Artist Profile Data (Weekly)'!$B:$B,$I16) -> 0 | K16: =IFERROR((J16-J15)/J15,0) -> 0
C17: DJ Maphorisa | D17: =SUMIFS('Artist Profile Data (Weekly)'!$K:$K,'Artist Profile Data (Weekly)'!$E:$E,$C17,'Artist Profile Data (Weekly)'!$B:$B,$D$2) -> 4458982 | E17: =SUMIFS('Artist Profile Data (Weekly)'!$L:$L,'Artist Profile Data (Weekly)'!$E:$E,$C17,'Artist Profile Data (Weekly)'!$B:$B,$D$2) -> 1463831442 | F17: =SUMIFS('Artist Profile Data (Weekly)'!$M:$M,'Artist Profile Data (Weekly)'!$E:$E,$C17,'Artist Profile Data (Weekly)'!$B:$B,D$2) -> 4691122 | G17: =IFERROR(F17/D17,0) -> 1.0520612 | I17: 13 | J17: =SUMIFS('Artist Profile Data (Weekly)'!$K:$K,'Artist Profile Data (Weekly)'!$A:$A,1,'Artist Profile Data (Weekly)'!$B:$B,$I17) -> 0 | K17: =IFERROR((J17-J16)/J16,0) -> 0
... C24: Kelvin Momo | D24: =SUMIFS('Artist Profile Data (Weekly)'!$K:$K,'Artist Profile Data (Weekly)'!$E:$E,$C24,'Artist Profile Data (Weekly)'!$B:$B,$D$2) -> 4669030 | E24: =SUMIFS('Artist Profile Data (Weekly)'!$L:$L,'Artist Profile Data (Weekly)'!$E:$E,$C24,'Artist Profile Data (Weekly)'!$B:$B,$D$2) -> 620779039 | F24: =SUMIFS('Artist Profile Data (Weekly)'!$M:$M,'Artist Profile Data (Weekly)'!$E:$E,$C24,'Artist Profile Data (Weekly)'!$B:$B,D$2) -> 1667314 | G24: =IFERROR(F24/D24,0) -> 0.35710073 | I24: 20 | J24: =SUMIFS('Artist Profile Data (Weekly)'!$K:$K,'Artist Profile Data (Weekly)'!$A:$A,1,'Artist Profile Data (Weekly)'!$B:$B,$I24) -> 0 | K24: =IFERROR((J24-J23)/J23,0) -> 0
C26: Total | D26: =SUBTOTAL(9,D5:D24) -> 36070934 | E26: =SUBTOTAL(9,E5:E24) -> 7393959069 | F26: =SUBTOTAL(9,F5:F24) -> 37848698

Sheet The Piano Index (3-Month)
A1: 2026
D2: 5 | E2: 6 | F2: 7
C3: Total Followers | H3: Growth Analysis
C4: Artist | D4: May | E4: June | F4: July | H4: May-June | I4: June-July | J4: May-July
C5: Thatohatsi | D5: =SUMIFS('Streaming Data (2024-2026)'!$F:$F,'Streaming Data (2024-2026)'!$D:$D,$C5,'Streaming Data (2024-2026)'!$B:$B,D$2,'Streaming Data (2024-2026)'!$A:$A,$A$1) -> 326254 | E5: =SUMIFS('Streaming Data (2024-2026)'!$F:$F,'Streaming Data (2024-2026)'!$D:$D,$C5,'Streaming Data (2024-2026)'!$B:$B,E$2,'Streaming Data (2024-2026)'!$A:$A,$A$1) -> 361146 | F5: =SUMIFS('Streaming Data (2024-2026)'!$F:$F,'Streaming Data (2024-2026)'!$D:$D,$C5,'Streaming Data (2024-2026)'!$B:$B,F$2,'Streaming Data (2024-2026)'!$A:$A,$A$1) -> 397115 | H5: =IFERROR((E5-D5)/D5,0) -> 0.10694735 | I5: =IFERROR((F5-E5)/E5,0) -> 0.099596839 | J5: =IFERROR((F5-D5)/D5,0) -> 0.2171958
C6: Sam Deep | D6: =SUMIFS('Streaming Data (2024-2026)'!$F:$F,'Streaming Data (2024-2026)'!$D:$D,$C6,'Streaming Data (2024-2026)'!$B:$B,D$2,'Streaming Data (2024-2026)'!$A:$A,$A$1) -> 1128567 | E6: =SUMIFS('Streaming Data (2024-2026)'!$F:$F,'Streaming Data (2024-2026)'!$D:$D,$C6,'Streaming Data (2024-2026)'!$B:$B,E$2,'Streaming Data (2024-2026)'!$A:$A,$A$1) -> 1191790 | F6: =SUMIFS('Streaming Data (2024-2026)'!$F:$F,'Streaming Data (2024-2026)'!$D:$D,$C6,'Streaming Data (2024-2026)'!$B:$B,F$2,'Streaming Data (2024-2026)'!$A:$A,$A$1) -> 1273152 | H6: =IFERROR((E6-D6)/D6,0) -> 0.0560206 | I6: =IFERROR((F6-E6)/E6,0) -> 0.068268739 | J6: =IFERROR((F6-D6)/D6,0) -> 0.12811379
C7: Uncool MC | D7: =SUMIFS('Streaming Data (2024-2026)'!$F:$F,'Streaming Data (2024-2026)'!$D:$D,$C7,'Streaming Data (2024-2026)'!$B:$B,D$2,'Streaming Data (2024-2026)'!$A:$A,$A$1) -> 71071 | E7: =SUMIFS('Streaming Data (2024-2026)'!$F:$F,'Streaming Data (2024-2026)'!$D:$D,$C7,'Streaming Data (2024-2026)'!$B:$B,E$2,'Streaming Data (2024-2026)'!$A:$A,$A$1) -> 75331 | F7: =SUMIFS('Streaming Data (2024-2026)'!$F:$F,'Streaming Data (2024-2026)'!$D:$D,$C7,'Streaming Data (2024-2026)'!$B:$B,F$2,'Streaming Data (2024-2026)'!$A:$A,$A$1) -> 79045 | H7: =IFERROR((E7-D7)/D7,0) -> 0.05994006 | I7: =IFERROR((F7-E7)/E7,0) -> 0.049302412 | J7: =IFERROR((F7-D7)/D7,0) -> 0.11219766
C8: XDuppy | D8: =SUMIFS('Streaming Data (2024-2026)'!$F:$F,'Streaming Data (2024-2026)'!$D:$D,$C8,'Streaming Data (2024-2026)'!$B:$B,D$2,'Streaming Data (2024-2026)'!$A:$A,$A$1) -> 442078 | E8: =SUMIFS('Streaming Data (2024-2026)'!$F:$F,'Streaming Data (2024-2026)'!$D:$D,$C8,'Streaming Data (2024-2026)'!$B:$B,E$2,'Streaming Data (2024-2026)'!$A:$A,$A$1) -> 470273 | F8: =SUMIFS('Streaming Data (2024-2026)'!$F:$F,'Streaming Data (2024-2026)'!$D:$D,$C8,'Streaming Data (2024-2026)'!$B:$B,F$2,'Streaming Data (2024-2026)'!$A:$A,$A$1) -> 491635 | H8: =IFERROR((E8-D8)/D8,0) -> 0.063778338 | I8: =IFERROR((F8-E8)/E8,0) -> 0.045424679 | J8: =IFERROR((F8-D8)/D8,0) -> 0.11210013
C9: TxC | D9: =SUMIFS('Streaming Data (2024-2026)'!$F:$F,'Streaming Data (2024-2026)'!$D:$D,$C9,'Streaming Data (2024-2026)'!$B:$B,D$2,'Streaming Data (2024-2026)'!$A:$A,$A$1) -> 293673 | E9: =SUMIFS('Streaming Data (2024-2026)'!$F:$F,'Streaming Data (2024-2026)'!$D:$D,$C9,'Streaming Data (2024-2026)'!$B:$B,E$2,'Streaming Data (2024-2026)'!$A:$A,$A$1) -> 309630 | F9: =SUMIFS('Streaming Data (2024-2026)'!$F:$F,'Streaming Data (2024-2026)'!$D:$D,$C9,'Streaming Data (2024-2026)'!$B:$B,F$2,'Streaming Data (2024-2026)'!$A:$A,$A$1) -> 318057 | H9: =IFERROR((E9-D9)/D9,0) -> 0.054335945 | I9: =IFERROR((F9-E9)/E9,0) -> 0.027216355 | J9: =IFERROR((F9-D9)/D9,0) -> 0.083031126
C10: Zee Nxumalo | D10: =SUMIFS('Streaming Data (2024-2026)'!$F:$F,'Streaming Data (2024-2026)'!$D:$D,$C10,'Streaming Data (2024-2026)'!$B:$B,D$2,'Streaming Data (2024-2026)'!$A:$A,$A$1) -> 1564098 | E10: =SUMIFS('Streaming Data (2024-2026)'!$F:$F,'Streaming Data (2024-2026)'!$D:$D,$C10,'Streaming Data (2024-2026)'!$B:$B,E$2,'Streaming Data (2024-2026)'!$A:$A,$A$1) -> 1634196 | F10: =SUMIFS('Streaming Data (2024-2026)'!$F:$F,'Streaming Data (2024-2026)'!$D:$D,$C10,'Streaming Data (2024-2026)'!$B:$B,F$2,'Streaming Data (2024-2026)'!$A:$A,$A$1) -> 1691439 | H10: =IFERROR((E10-D10)/D10,0) -> 0.044816885 | I10: =IFERROR((F10-E10)/E10,0) -> 0.035028234 | J10: =IFERROR((F10-D10)/D10,0) -> 0.081414975
C11: Scotts Maphuma | D11: =SUMIFS('Streaming Data (2024-2026)'!$F:$F,'Streaming Data (2024-2026)'!$D:$D,$C11,'Streaming Data (2024-2026)'!$B:$B,D$2,'Streaming Data (2024-2026)'!$A:$A,$A$1) -> 1706291 | E11: =SUMIFS('Streaming Data (2024-2026)'!$F:$F,'Streaming Data (2024-2026)'!$D:$D,$C11,'Streaming Data (2024-2026)'!$B:$B,E$2,'Streaming Data (2024-2026)'!$A:$A,$A$1) -> 1775021 | F11: =SUMIFS('Streaming Data (2024-2026)'!$F:$F,'Streaming Data (2024-2026)'!$D:$D,$C11,'Streaming Data (2024-2026)'!$B:$B,F$2,'Streaming Data (2024-2026)'!$A:$A,$A$1) -> 1836645 | H11: =IFERROR((E11-D11)/D11,0) -> 0.040280351 | I11: =IFERROR((F11-E11)/E11,0) -> 0.034717336 | J11: =IFERROR((F11-D11)/D11,0) -> 0.076396113
C12: Pcee | D12: =SUMIFS('Streaming Data (2024-2026)'!$F:$F,'Streaming Data (2024-2026)'!$D:$D,$C12,'Streaming Data (2024-2026)'!$B:$B,D$2,'Streaming Data (2024-2026)'!$A:$A,$A$1) -> 755355 | E12: =SUMIFS('Streaming Data (2024-2026)'!$F:$F,'Streaming Data (2024-2026)'!$D:$D,$C12,'Streaming Data (2024-2026)'!$B:$B,E$2,'Streaming Data (2024-2026)'!$A:$A,$A$1) -> 780255 | F12: =SUMIFS('Streaming Data (2024-2026)'!$F:$F,'Streaming Data (2024-2026)'!$D:$D,$C12,'Streaming Data (2024-2026)'!$B:$B,F$2,'Streaming Data (2024-2026)'!$A:$A,$A$1) -> 802257 | H12: =IFERROR((E12-D12)/D12,0) -> 0.032964633 | I12: =IFERROR((F12-E12)/E12,0) -> 0.028198474 | J12: =IFERROR((F12-D12)/D12,0) -> 0.062092658
C13: Royal Musiq | D13: =SUMIFS('Streaming Data (2024-2026)'!$F:$F,'Streaming Data (2024-2026)'!$D:$D,$C13,'Streaming Data (2024-2026)'!$B:$B,D$2,'Streaming Data (2024-2026)'!$A:$A,$A$1) -> 245041 | E13: =SUMIFS('Streaming Data (2024-2026)'!$F:$F,'Streaming Data (2024-2026)'!$D:$D,$C13,'Streaming Data (2024-2026)'!$B:$B,E$2,'Streaming Data (2024-2026)'!$A:$A,$A$1) -> 251255 | F13: =SUMIFS('Streaming Data (2024-2026)'!$F:$F,'Streaming Data (2024-2026)'!$D:$D,$C13,'Streaming Data (2024-2026)'!$B:$B,F$2,'Streaming Data (2024-2026)'!$A:$A,$A$1) -> 257555 | H13: =IFERROR((E13-D13)/D13,0) -> 0.025359022 | I13: =IFERROR((F13-E13)/E13,0) -> 0.025074128 | J13: =IFERROR((F13-D13)/D13,0) -> 0.051069005
C14: Kelvin Momo | D14: =SUMIFS('Streaming Data (2024-2026)'!$F:$F,'Streaming Data (2024-2026)'!$D:$D,$C14,'Streaming Data (2024-2026)'!$B:$B,D$2,'Streaming Data (2024-2026)'!$A:$A,$A$1) -> 4455569 | E14: =SUMIFS('Streaming Data (2024-2026)'!$F:$F,'Streaming Data (2024-2026)'!$D:$D,$C14,'Streaming Data (2024-2026)'!$B:$B,E$2,'Streaming Data (2024-2026)'!$A:$A,$A$1) -> 4576550 | F14: =SUMIFS('Streaming Data (2024-2026)'!$F:$F,'Streaming Data (2024-2026)'!$D:$D,$C14,'Streaming Data (2024-2026)'!$B:$B,F$2,'Streaming Data (2024-2026)'!$A:$A,$A$1) -> 4665879 | H14: =IFERROR((E14-D14)/D14,0) -> 0.027152761 | I14: =IFERROR((F14-E14)/E14,0) -> 0.019518852 | J14: =IFERROR((F14-D14)/D14,0) -> 0.047201603
C15: Justin99 | D15: =SUMIFS('Streaming Data (2024-2026)'!$F:$F,'Streaming Data (2024-2026)'!$D:$D,$C15,'Streaming Data (2024-2026)'!$B:$B,D$2,'Streaming Data (2024-2026)'!$A:$A,$A$1) -> 420847 | E15: =SUMIFS('Streaming Data (2024-2026)'!$F:$F,'Streaming Data (2024-2026)'!$D:$D,$C15,'Streaming Data (2024-2026)'!$B:$B,E$2,'Streaming Data (2024-2026)'!$A:$A,$A$1) -> 427745 | F15: =SUMIFS('Streaming Data (2024-2026)'!$F:$F,'Streaming Data (2024-2026)'!$D:$D,$C15,'Streaming Data (2024-2026)'!$B:$B,F$2,'Streaming Data (2024-2026)'!$A:$A,$A$1) -> 439293 | H15: =IFERROR((E15-D15)/D15,0) -> 0.016390755 | I15: =IFERROR((F15-E15)/E15,0) -> 0.026997393 | J15: =IFERROR((F15-D15)/D15,0) -> 0.043830656
C16: DJ Maphorisa | D16: =SUMIFS('Streaming Data (2024-2026)'!$F:$F,'Streaming Data (2024-2026)'!$D:$D,$C16,'Streaming Data (2024-2026)'!$B:$B,D$2,'Streaming Data (2024-2026)'!$A:$A,$A$1) -> 4286302 | E16: =SUMIFS('Streaming Data (2024-2026)'!$F:$F,'Streaming Data (2024-2026)'!$D:$D,$C16,'Streaming Data (2024-2026)'!$B:$B,E$2,'Streaming Data (2024-2026)'!$A:$A,$A$1) -> 4381160 | F16: =SUMIFS('Streaming Data (2024-2026)'!$F:$F,'Streaming Data (2024-2026)'!$D:$D,$C16,'Streaming Data (2024-2026)'!$B:$B,F$2,'Streaming Data (2024-2026)'!$A:$A,$A$1) -> 4456656 | H16: =IFERROR((E16-D16)/D16,0) -> 0.022130499 | I16: =IFERROR((F16-E16)/E16,0) -> 0.017231966 | J16: =IFERROR((F16-D16)/D16,0) -> 0.039743816
... C24: Tyler ICU | D24: =SUMIFS('Streaming Data (2024-2026)'!$F:$F,'Streaming Data (2024-2026)'!$D:$D,$C24,'Streaming Data (2024-2026)'!$B:$B,D$2,'Streaming Data (2024-2026)'!$A:$A,$A$1) -> 1540959 | E24: =SUMIFS('Streaming Data (2024-2026)'!$F:$F,'Streaming Data (2024-2026)'!$D:$D,$C24,'Streaming Data (2024-2026)'!$B:$B,E$2,'Streaming Data (2024-2026)'!$A:$A,$A$1) -> 1545812 | F24: =SUMIFS('Streaming Data (2024-2026)'!$F:$F,'Streaming Data (2024-2026)'!$D:$D,$C24,'Streaming Data (2024-2026)'!$B:$B,F$2,'Streaming Data (2024-2026)'!$A:$A,$A$1) -> 1550966 | H24: =IFERROR((E24-D24)/D24,0) -> 0.0031493375 | I24: =IFERROR((F24-E24)/E24,0) -> 0.00333417 | J24: =IFERROR((F24-D24)/D24,0) -> 0.006494008
C27: Total Streams | H27: Growth Analysis
C28: Artist | D28: May | E28: June | F28: July | H28: May-June | I28: June-July | J28: May-July
C29: Thatohatsi | D29: =SUMIFS('Streaming Data (2024-2026)'!$H:$H,'Streaming Data (2024-2026)'!$D:$D,$C29,'Streaming Data (2024-2026)'!$B:$B,D$2,'Streaming Data (2024-2026)'!$A:$A,$A$1) -> 199470478 | E29: =SUMIFS('Streaming Data (2024-2026)'!$H:$H,'Streaming Data (2024-2026)'!$D:$D,$C29,'Streaming Data (2024-2026)'!$B:$B,E$2,'Streaming Data (2024-2026)'!$A:$A,$A$1) -> 216330865 | F29: =SUMIFS('Streaming Data (2024-2026)'!$H:$H,'Streaming Data (2024-2026)'!$D:$D,$C29,'Streaming Data (2024-2026)'!$B:$B,F$2,'Streaming Data (2024-2026)'!$A:$A,$A$1) -> 232932135 | H29: =IFERROR((E29-D29)/D29,0) -> 0.084525726 | I29: =IFERROR((F29-E29)/E29,0) -> 0.076740182 | J29: =IFERROR((F29-D29)/D29,0) -> 0.16775243
